Workbook

Sheet Summary
G5: Consumer + Storage Device Economic Model
C6: Project Summary
C13: NPV (₪) | F13: Battery Capacity | I13: Equity IRR (%) | L13: Project IRR (%) | P13: Average Annual Gross Yield (%) | T13: Payback Period (Years)
C14: ='Tabular Data'!N92 -> 3790987.3 | F14: ='Tabular Data'!N20 -> 2280 | I14: ='Tabular Data'!N93 -> 0.65712387 | L14: ='Tabular Data'!N94 -> 0.23382336 | P14: ='Tabular Data'!N95 -> 0.22195841 | T14: ='Tabular Data'!N96 -> 3.9856839
C20: Seasonal Energy Consumption Patterns
D28: Before Storage
D30: Total Consumption (kWh) | H30: ='Tabular Data'!G39 -> 6263338
D31: Total Annual Cost (₪) | H31: ='Tabular Data'!G40 -> 3220724
H33: Consumption (kWh) | I33: Cost (₪)
D34: Peak | F34: Summer | H34: ='Tabular Data'!I43 -> 484210.12 | I34: ='Tabular Data'!J43 -> 693292.05
F35: Winter | H35: ='Tabular Data'!I44 -> 276737.84 | I35: ='Tabular Data'!J44 -> 283102.81
F36: Transitional Seasons | H36: ='Tabular Data'!I45 -> 373843.08 | I36: ='Tabular Data'!J45 -> 157687.01
D38: Low | F38: Summer | H38: ='Tabular Data'!I47 -> 1999715 | I38: ='Tabular Data'!J47 -> 895272.41
F39: Winter | H39: ='Tabular Data'!I48 -> 1057466.7 | I39: ='Tabular Data'!J48 -> 408393.65
F40: Transitional Seasons | H40: ='Tabular Data'!I49 -> 2071365.2 | I40: ='Tabular Data'!J49 -> 782976.06
D43: With Storage
D45: Total Consumption (kWh) | H45: ='Tabular Data'!Q39 -> 6302803.6
D46: Total Annual Cost (₪) | H46: ='Tabular Data'!Q40 -> 2948624.9
H48: Consumption (kWh) | I48: Cost (₪)
D49: Peak | F49: Summer | H49: ='Tabular Data'!S43 -> 304588.08 | I49: ='Tabular Data'!T43 -> 436109.21 | J49: Description
F50: Winter | H50: ='Tabular Data'!S44 -> 101169.17 | I50: ='Tabular Data'!T44 -> 103496.06
F51: Transitional Seasons | H51: ='Tabular Data'!S45 -> 373843.08 | I51: ='Tabular Data'!T45 -> 157687.01 | J51: This chart illustrates the daily energy consumption during low and peak hours across different seasons: winter, summer, and transitional seasons. The histograms compare energy usage levels. The x-axis represents daily energy consumption in kilowatt-hours (kWh), while the y-axis indicates the frequency of days each consumption level is observed. This visualization aids in understanding the variations in energy consumption across seasons and time periods.
D53: Low | F53: Summer | H53: ='Tabular Data'!S47 -> 2199295 | I53: ='Tabular Data'!T47 -> 984624.39
F54: Winter | H54: ='Tabular Data'!S48 -> 1252543 | I54: ='Tabular Data'!T48 -> 483732.11
F55: Transitional Seasons | H55: ='Tabular Data'!S49 -> 2071365.2 | I55: ='Tabular Data'!T49 -> 782976.06
C58: Optimal Storage Size
L65: Description | R65: Parameters
L67: ="his graph shows how the Project Internal Rate of Return (PIRR) changes with the size of the storage device (battery capacity). The x-axis represents the battery capacity in kilowatt-hours (kWh), and the y-axis shows the Project IRR." & "The optimal storage capacity, which maximizes the Project IRR, is " & 'Tabular Data'!D57 & " kWh." -> his graph shows how the Project Internal Rate of Return (PIRR) changes with the size of the storage device (battery capacity). The x-axis represents the battery capacity in kilowatt-hours (kWh), and the y-axis shows the Project IRR.The optimal storage capacity, which maximizes the Project IRR, is kWh. | R67: Global Constants | T67: Exchange Rate (₪/$) | W67: ='Tabular Data'!I11 -> 3.7
T68: Inflation Rate | W68: ='Tabular Data'!I12 -> 0.06
T69: Prime Interest Rate | W69: ='Tabular Data'!I13 -> 0.06
T70: Discount Rate | W70: ='Tabular Data'!I14 -> 0.05
R72: Financing Details | T72: Marginal Annual Interest Rate | W72: =Summary!S11 -> 0
T73: Marginal Annual Interest Rate Growth | W73: =Summary!S12 -> 0
T74: Repayment Period (Years) | W74: =Summary!S13 -> 0
T75: Own Funds Ratio | W75: =Summary!S14 -> 0
T76: Voltage Type | W76: ='Tabular Data'!S15 -> Low Voltage General Consumer IEC
R78: Capital Expenditure (Capex) | T78: Initial Capex (₪) | W78: ='Tabular Data'!N26 -> 0
T79: Annual Opex (₪) | W79: ='Tabular Data'!N27 -> 0
R81: Additional Specifications | T81: Response Time Window (hr) | W81: ='Tabular Data'!N19 -> <0.5
T82: Battery Cost per kWh ($) | W82: ='Tabular Data'!N18 -> 230
...

Sheet Tabular Data
B1: Economic Model For Storage Device
K3: Contact Information | M3: גל זלוף
B8: Parameters
E10: Global Constants | O10: Financing Details
E11: Exchange Rate (₪/$) | I11: 3.7 | O11: Marginal Annual Interest Rate | S11: 0.02
E12: Inflation Rate | I12: 0.06 | O12: Marginal Annual Interest Rate Growth
E13: Prime Interest Rate | I13: 0.06 | O13: Repayment Period (Years) | S13: 10
E14: Discount Rate | I14: 0.05 | O14: Own Funds Ratio | S14: 0.2
O15: Voltage Type | S15: Low Voltage General Consumer IEC
E17: Additional Specifications
E18: Battery Cost per kWh ($) | N18: 230
E19: Response Time Window (hr) | N19: <0.5
E20: Battery Size (kWh) | N20: 2280
E21: Annual Degradation | N21: 0.02
E22: Round-Trip-Efficiency | N22: 0.9
E23: Depth-of-Discharge | N23: 1
E25: Capital Expenditure (Capex)
E26: Initial Capex (₪) | N26: 0
E27: Annual Opex (₪)
B33: Annual Consumption Data Summary
E36: Before Storage | O36: With Storage
E39: Total Consumption (kWh) | G39: 6263338 | O39: Total Consumption (kWh) | Q39: 6302803.6
E40: Total Annual Cost (₪) | G40: 3220724 | O40: Total Annual Cost (₪) | Q40: 2948624.9
I42: Consumption (kWh) | J42: Cost (₪) | S42: Consumption (kWh) | T42: Cost (₪)
E43: Peak | G43: Summer | I43: 484210.12 | J43: 693292.05 | O43: Peak | Q43: Summer | S43: 304588.08 | T43: 436109.21
G44: Winter | I44: 276737.84 | J44: 283102.81 | K44: שעות יקרות | Q44: Winter | S44: 101169.17 | T44: 103496.06
G45: Transitional Seasons | I45: 373843.08 | J45: 157687.01 | K45: =J45+J44+J43 -> 1134081.9 | L45: =U45 -> 697292.29 | M45: =L45-K45 -> -436789.58 | Q45: Transitional Seasons | S45: 373843.08 | T45: 157687.01 | U45: =SUM(T43:T45) -> 697292.29
E47: Low | G47: Summer | I47: 1999715 | J47: 895272.41 | O47: Low | Q47: Summer | S47: 2199295 | T47: 984624.39
G48: Winter | I48: 1057466.7 | J48: 408393.65 | K48: שעות זולות | Q48: Winter | S48: 1252543 | T48: 483732.11
G49: Transitional Seasons | I49: 2071365.2 | J49: 782976.06 | K49: =J49+J48+J47 -> 2086642.1 | L49: =U49 -> 2251332.6 | M49: =L49-K49 -> 164690.45 | Q49: Transitional Seasons | S49: 2071365.2 | T49: 782976.06 | U49: =SUM(T47:T49) -> 2251332.6
M50: =M49+M45 -> -272099.13
B53: Yearly Revenues Aggregation
I55: Total number of cycles per year | K55: Battery Cost (₪) | M55: Project Cost (₪) | O55: Equity (₪)
I56: 176 | K56: 1940280 | M56: 1940280 | O56: 388056
E58: חיסכון תעו״ז | F58: מכירה
D59: Year | E59: Revenue (₪) | H59: Expenses | M59: Project Cash Flow | O59: Financing | S59: Free Cash Flow | U59: Gross Yield on Equity
E61: Load Shifting | F61: Load Shedding | G61: Total Revenue | H61: Management Fees | I61: Insurance | J61: o&m | K61: Unexpected Costs | L61: Total Expenses | M61: Per Year | N61: Cumulative | O61: fund | P61: repayment | Q61: interest | R61: total | S61: per year | T61: cumulative
D62: 0 | E62: 0 | F62: 0 | G62: 0 | H62: 0 | I62: 0 | J62: 0 | K62: 0 | L62: 0 | M62: -1940280 | N62: -1940280 | O62: 1552224 | P62: 0 | Q62: 0 | R62: 0 | S62: -388056 | T62: -388056 | U62: 0
D63: 1 | E63: 272099.13 | F63: 251629.91 | G63: 523729.04 | H63: 15711.871 | I63: 11400 | J63: 0 | K63: 3000 | L63: 30111.871 | M63: 493617.17 | N63: -1446662.8 | O63: 1445074.8 | P63: 107149.23 | Q63: 124177.92 | R63: 231327.15 | S63: 262290.02 | T63: -125765.98 | U63: 0.25440512
D64: 2 | E64: 267342.51 | F64: 251629.91 | G64: 518972.43 | H64: 15569.173 | I64: 11400 | J64: 0 | K64: 3000 | L64: 29969.173 | M64: 489003.25 | N64: -957659.58 | O64: 1329353.6 | P64: 115721.17 | Q64: 115605.98 | R64: 231327.15 | S64: 257676.1 | T64: 131910.13 | U64: 0.25202716
...
